2020-10-06 13:47:34,066 ERROR: Exception on /reset_password_request [POST] [in /Users/dhyungseoklee/Projects/Flask/virtual_env/flask_env/lib/python3.7/site-packages/flask/app.py:1892]
Traceback (most recent call last):
  File "/Users/dhyungseoklee/Projects/Flask/virtual_env/flask_env/lib/python3.7/site-packages/flask/app.py", line 2447, in wsgi_app
    response = self.full_dispatch_request()
  File "/Users/dhyungseoklee/Projects/Flask/virtual_env/flask_env/lib/python3.7/site-packages/flask/app.py", line 1952, in full_dispatch_request
    rv = self.handle_user_exception(e)
  File "/Users/dhyungseoklee/Projects/Flask/virtual_env/flask_env/lib/python3.7/site-packages/flask/app.py", line 1821, in handle_user_exception
    reraise(exc_type, exc_value, tb)
  File "/Users/dhyungseoklee/Projects/Flask/virtual_env/flask_env/lib/python3.7/site-packages/flask/_compat.py", line 39, in reraise
    raise value
  File "/Users/dhyungseoklee/Projects/Flask/virtual_env/flask_env/lib/python3.7/site-packages/flask/app.py", line 1950, in full_dispatch_request
    rv = self.dispatch_request()
  File "/Users/dhyungseoklee/Projects/Flask/virtual_env/flask_env/lib/python3.7/site-packages/flask/app.py", line 1936, in dispatch_request
    return self.view_functions[rule.endpoint](**req.view_args)
  File "/Users/dhyungseoklee/Projects/Flask/microblog/app/routes.py", line 166, in reset_password_request
    send_password_reset_email(user)
  File "/Users/dhyungseoklee/Projects/Flask/microblog/app/email.py", line 19, in send_password_reset_email
    html_body = render_template('email/reset_password.html', user=user, token=token))
  File "/Users/dhyungseoklee/Projects/Flask/virtual_env/flask_env/lib/python3.7/site-packages/flask/templating.py", line 138, in render_template
    ctx.app.jinja_env.get_or_select_template(template_name_or_list),
  File "/Users/dhyungseoklee/Projects/Flask/virtual_env/flask_env/lib/python3.7/site-packages/jinja2/environment.py", line 930, in get_or_select_template
    return self.get_template(template_name_or_list, parent, globals)
  File "/Users/dhyungseoklee/Projects/Flask/virtual_env/flask_env/lib/python3.7/site-packages/jinja2/environment.py", line 883, in get_template
    return self._load_template(name, self.make_globals(globals))
  File "/Users/dhyungseoklee/Projects/Flask/virtual_env/flask_env/lib/python3.7/site-packages/jinja2/environment.py", line 857, in _load_template
    template = self.loader.load(self, name, globals)
  File "/Users/dhyungseoklee/Projects/Flask/virtual_env/flask_env/lib/python3.7/site-packages/jinja2/loaders.py", line 127, in load
    code = environment.compile(source, name, filename)
  File "/Users/dhyungseoklee/Projects/Flask/virtual_env/flask_env/lib/python3.7/site-packages/jinja2/environment.py", line 638, in compile
    self.handle_exception(source=source_hint)
  File "/Users/dhyungseoklee/Projects/Flask/virtual_env/flask_env/lib/python3.7/site-packages/jinja2/environment.py", line 832, in handle_exception
    reraise(*rewrite_traceback_stack(source=source))
  File "/Users/dhyungseoklee/Projects/Flask/virtual_env/flask_env/lib/python3.7/site-packages/jinja2/_compat.py", line 28, in reraise
    raise value.with_traceback(tb)
  File "/Users/dhyungseoklee/Projects/Flask/microblog/app/templates/email/reset_password.html", line 8, in template
    <p>{{ url_for('reset_password', token=token, _external=True }}</p>
jinja2.exceptions.TemplateSyntaxError: unexpected '}', expected ')'
2020-10-06 13:47:54,608 INFO: Microblog startup [in /Users/dhyungseoklee/Projects/Flask/microblog/app/__init__.py:45]
2020-10-06 13:48:01,280 ERROR: Exception on /reset_password_request [POST] [in /Users/dhyungseoklee/Projects/Flask/virtual_env/flask_env/lib/python3.7/site-packages/flask/app.py:1892]
Traceback (most recent call last):
  File "/Users/dhyungseoklee/Projects/Flask/virtual_env/flask_env/lib/python3.7/site-packages/flask/app.py", line 2447, in wsgi_app
    response = self.full_dispatch_request()
  File "/Users/dhyungseoklee/Projects/Flask/virtual_env/flask_env/lib/python3.7/site-packages/flask/app.py", line 1952, in full_dispatch_request
    rv = self.handle_user_exception(e)
  File "/Users/dhyungseoklee/Projects/Flask/virtual_env/flask_env/lib/python3.7/site-packages/flask/app.py", line 1821, in handle_user_exception
    reraise(exc_type, exc_value, tb)
  File "/Users/dhyungseoklee/Projects/Flask/virtual_env/flask_env/lib/python3.7/site-packages/flask/_compat.py", line 39, in reraise
    raise value
  File "/Users/dhyungseoklee/Projects/Flask/virtual_env/flask_env/lib/python3.7/site-packages/flask/app.py", line 1950, in full_dispatch_request
    rv = self.dispatch_request()
  File "/Users/dhyungseoklee/Projects/Flask/virtual_env/flask_env/lib/python3.7/site-packages/flask/app.py", line 1936, in dispatch_request
    return self.view_functions[rule.endpoint](**req.view_args)
  File "/Users/dhyungseoklee/Projects/Flask/microblog/app/routes.py", line 166, in reset_password_request
    send_password_reset_email(user)
  File "/Users/dhyungseoklee/Projects/Flask/microblog/app/email.py", line 19, in send_password_reset_email
    html_body = render_template('email/reset_password.html', user=user, token=token))
  File "/Users/dhyungseoklee/Projects/Flask/microblog/app/email.py", line 10, in send_mail
    mail.send(msg)
  File "/Users/dhyungseoklee/Projects/Flask/virtual_env/flask_env/lib/python3.7/site-packages/flask_mail.py", line 491, in send
    with self.connect() as connection:
  File "/Users/dhyungseoklee/Projects/Flask/virtual_env/flask_env/lib/python3.7/site-packages/flask_mail.py", line 144, in __enter__
    self.host = self.configure_host()
  File "/Users/dhyungseoklee/Projects/Flask/virtual_env/flask_env/lib/python3.7/site-packages/flask_mail.py", line 158, in configure_host
    host = smtplib.SMTP(self.mail.server, self.mail.port)
  File "/usr/local/Cellar/python/3.7.6_1/Frameworks/Python.framework/Versions/3.7/lib/python3.7/smtplib.py", line 251, in __init__
    (code, msg) = self.connect(host, port)
  File "/usr/local/Cellar/python/3.7.6_1/Frameworks/Python.framework/Versions/3.7/lib/python3.7/smtplib.py", line 336, in connect
    self.sock = self._get_socket(host, port, self.timeout)
  File "/usr/local/Cellar/python/3.7.6_1/Frameworks/Python.framework/Versions/3.7/lib/python3.7/smtplib.py", line 307, in _get_socket
    self.source_address)
  File "/usr/local/Cellar/python/3.7.6_1/Frameworks/Python.framework/Versions/3.7/lib/python3.7/socket.py", line 728, in create_connection
    raise err
  File "/usr/local/Cellar/python/3.7.6_1/Frameworks/Python.framework/Versions/3.7/lib/python3.7/socket.py", line 716, in create_connection
    sock.connect(sa)
ConnectionRefusedError: [Errno 61] Connection refused
2020-10-06 13:49:24,275 INFO: Microblog startup [in /Users/dhyungseoklee/Projects/Flask/microblog/app/__init__.py:45]
2020-10-06 14:00:18,420 INFO: Microblog startup [in /Users/dhyungseoklee/Projects/Flask/microblog/app/__init__.py:45]
2020-10-06 14:00:40,597 INFO: Microblog startup [in /Users/dhyungseoklee/Projects/Flask/microblog/app/__init__.py:45]
2020-10-06 14:02:17,771 INFO: Microblog startup [in /Users/dhyungseoklee/Projects/Flask/microblog/app/__init__.py:45]
