2020-10-06 14:12:05,197 ERROR: Exception on /reset_password_request [POST] [in /Users/dhyungseoklee/Projects/Flask/virtual_env/flask_env/lib/python3.7/site-packages/flask/app.py:1892]
Traceback (most recent call last):
  File "/Users/dhyungseoklee/Projects/Flask/virtual_env/flask_env/lib/python3.7/site-packages/flask/app.py", line 2447, in wsgi_app
    response = self.full_dispatch_request()
  File "/Users/dhyungseoklee/Projects/Flask/virtual_env/flask_env/lib/python3.7/site-packages/flask/app.py", line 1952, in full_dispatch_request
    rv = self.handle_user_exception(e)
  File "/Users/dhyungseoklee/Projects/Flask/virtual_env/flask_env/lib/python3.7/site-packages/flask/app.py", line 1821, in handle_user_exception
    reraise(exc_type, exc_value, tb)
  File "/Users/dhyungseoklee/Projects/Flask/virtual_env/flask_env/lib/python3.7/site-packages/flask/_compat.py", line 39, in reraise
    raise value
  File "/Users/dhyungseoklee/Projects/Flask/virtual_env/flask_env/lib/python3.7/site-packages/flask/app.py", line 1950, in full_dispatch_request
    rv = self.dispatch_request()
  File "/Users/dhyungseoklee/Projects/Flask/virtual_env/flask_env/lib/python3.7/site-packages/flask/app.py", line 1936, in dispatch_request
    return self.view_functions[rule.endpoint](**req.view_args)
  File "/Users/dhyungseoklee/Projects/Flask/microblog/app/routes.py", line 166, in reset_password_request
    send_password_reset_email(user)
  File "/Users/dhyungseoklee/Projects/Flask/microblog/app/mail.py", line 19, in send_password_reset_email
    html_body = render_template('mail/reset_password.html', user=user, token=token))
  File "/Users/dhyungseoklee/Projects/Flask/microblog/app/mail.py", line 10, in send_mail
    mail.send(msg)
  File "/Users/dhyungseoklee/Projects/Flask/virtual_env/flask_env/lib/python3.7/site-packages/flask_mail.py", line 491, in send
    with self.connect() as connection:
  File "/Users/dhyungseoklee/Projects/Flask/virtual_env/flask_env/lib/python3.7/site-packages/flask_mail.py", line 144, in __enter__
    self.host = self.configure_host()
  File "/Users/dhyungseoklee/Projects/Flask/virtual_env/flask_env/lib/python3.7/site-packages/flask_mail.py", line 158, in configure_host
    host = smtplib.SMTP(self.mail.server, self.mail.port)
  File "/usr/local/Cellar/python/3.7.6_1/Frameworks/Python.framework/Versions/3.7/lib/python3.7/smtplib.py", line 251, in __init__
    (code, msg) = self.connect(host, port)
  File "/usr/local/Cellar/python/3.7.6_1/Frameworks/Python.framework/Versions/3.7/lib/python3.7/smtplib.py", line 336, in connect
    self.sock = self._get_socket(host, port, self.timeout)
  File "/usr/local/Cellar/python/3.7.6_1/Frameworks/Python.framework/Versions/3.7/lib/python3.7/smtplib.py", line 307, in _get_socket
    self.source_address)
  File "/usr/local/Cellar/python/3.7.6_1/Frameworks/Python.framework/Versions/3.7/lib/python3.7/socket.py", line 728, in create_connection
    raise err
  File "/usr/local/Cellar/python/3.7.6_1/Frameworks/Python.framework/Versions/3.7/lib/python3.7/socket.py", line 716, in create_connection
    sock.connect(sa)
ConnectionRefusedError: [Errno 61] Connection refused
2020-10-06 14:15:19,135 INFO: Microblog startup [in /Users/dhyungseoklee/Projects/Flask/microblog/app/__init__.py:45]
2020-10-06 14:15:33,441 ERROR: Exception on /reset_password_request [POST] [in /Users/dhyungseoklee/Projects/Flask/virtual_env/flask_env/lib/python3.7/site-packages/flask/app.py:1892]
Traceback (most recent call last):
  File "/Users/dhyungseoklee/Projects/Flask/virtual_env/flask_env/lib/python3.7/site-packages/flask/app.py", line 2447, in wsgi_app
    response = self.full_dispatch_request()
  File "/Users/dhyungseoklee/Projects/Flask/virtual_env/flask_env/lib/python3.7/site-packages/flask/app.py", line 1952, in full_dispatch_request
    rv = self.handle_user_exception(e)
  File "/Users/dhyungseoklee/Projects/Flask/virtual_env/flask_env/lib/python3.7/site-packages/flask/app.py", line 1821, in handle_user_exception
    reraise(exc_type, exc_value, tb)
  File "/Users/dhyungseoklee/Projects/Flask/virtual_env/flask_env/lib/python3.7/site-packages/flask/_compat.py", line 39, in reraise
    raise value
  File "/Users/dhyungseoklee/Projects/Flask/virtual_env/flask_env/lib/python3.7/site-packages/flask/app.py", line 1950, in full_dispatch_request
    rv = self.dispatch_request()
  File "/Users/dhyungseoklee/Projects/Flask/virtual_env/flask_env/lib/python3.7/site-packages/flask/app.py", line 1936, in dispatch_request
    return self.view_functions[rule.endpoint](**req.view_args)
  File "/Users/dhyungseoklee/Projects/Flask/microblog/app/routes.py", line 166, in reset_password_request
    send_password_reset_email(user)
  File "/Users/dhyungseoklee/Projects/Flask/microblog/app/mail.py", line 19, in send_password_reset_email
    html_body = render_template('mail/reset_password.html', user=user, token=token))
  File "/Users/dhyungseoklee/Projects/Flask/microblog/app/mail.py", line 10, in send_mail
    mail.send(msg)
  File "/Users/dhyungseoklee/Projects/Flask/virtual_env/flask_env/lib/python3.7/site-packages/flask_mail.py", line 491, in send
    with self.connect() as connection:
  File "/Users/dhyungseoklee/Projects/Flask/virtual_env/flask_env/lib/python3.7/site-packages/flask_mail.py", line 144, in __enter__
    self.host = self.configure_host()
  File "/Users/dhyungseoklee/Projects/Flask/virtual_env/flask_env/lib/python3.7/site-packages/flask_mail.py", line 158, in configure_host
    host = smtplib.SMTP(self.mail.server, self.mail.port)
  File "/usr/local/Cellar/python/3.7.6_1/Frameworks/Python.framework/Versions/3.7/lib/python3.7/smtplib.py", line 251, in __init__
    (code, msg) = self.connect(host, port)
  File "/usr/local/Cellar/python/3.7.6_1/Frameworks/Python.framework/Versions/3.7/lib/python3.7/smtplib.py", line 336, in connect
    self.sock = self._get_socket(host, port, self.timeout)
  File "/usr/local/Cellar/python/3.7.6_1/Frameworks/Python.framework/Versions/3.7/lib/python3.7/smtplib.py", line 307, in _get_socket
    self.source_address)
  File "/usr/local/Cellar/python/3.7.6_1/Frameworks/Python.framework/Versions/3.7/lib/python3.7/socket.py", line 728, in create_connection
    raise err
  File "/usr/local/Cellar/python/3.7.6_1/Frameworks/Python.framework/Versions/3.7/lib/python3.7/socket.py", line 716, in create_connection
    sock.connect(sa)
ConnectionRefusedError: [Errno 61] Connection refused
2020-10-06 17:36:23,930 INFO: Microblog startup [in /Users/dhyungseoklee/Projects/Flask/microblog/app/__init__.py:45]
